2021-12-08 19:52:07,547:ERROR:Cannot make the connection with https://ghibliapi.herokuapp.com/films 
2021-12-08 20:17:49,253:ERROR:Cannot make the connection with https://ghibliapi.erokuapp.com/films
2021-12-08 21:14:58,902:ERROR:Cannot make the connection with https://ghibliapi.erokuapp.com/films
2021-12-08 21:18:06,944:ERROR:Cannot make the connection with https://ghibliapi.erokuapp.com/films
2021-12-08 21:18:55,432:ERROR:response_data has value None
2021-12-08 21:21:07,177:ERROR:Cannot make the connection with https://ghibliapi.erokuapp.com/films
2021-12-08 21:21:52,680:ERROR:response_data has value None
2021-12-08 21:24:56,539:ERROR:Cannot make the connection with https://ghibliapi.erokuapp.com/films
2021-12-08 21:37:29,024:ERROR:Cannot make the connection with https://ghibliapi.erokuapp.com/films
2021-12-08 21:39:39,583:ERROR:ConnectionError: Cannot make the connection with https://ghibliapi.erokuapp.com/films
2021-12-08 21:40:37,383:ERROR:MissingSchema: Cannot make the connection with 
2021-12-08 21:43:25,708:ERROR:ConnectionError: Cannot make the connection with https://ghibliapi.herokuapp.com/film
2021-12-08 21:51:52,429:INFO:Empty DataFrame
Columns: []
Index: []
2021-12-08 21:53:45,236:WARNING:Empty DataFrame
Columns: []
Index: []
2021-12-08 21:54:13,876:ERROR:Empty DataFrame
Columns: []
Index: []
2021-12-08 22:02:25,956:ERROR:MissingSchema: Cannot make the connection with 
2021-12-08 22:05:11,388:WARNING:override steps (5) and chunk_size (512) as content does not fit (494 byte(s) given) parameters.
2021-12-08 22:05:11,388:INFO:Detected declarative mark in sequence. Priority +1 given for utf_8.
2021-12-08 22:05:11,436:INFO:utf_8 passed initial chaos probing. Mean measured chaos is 0.000000 %
2021-12-08 22:05:11,441:INFO:We detected language [('English', 1.0), ('Dutch', 1.0), ('Norwegian', 1.0)] using utf_8
2021-12-08 22:05:11,441:INFO:utf_8 is most likely the one. Stopping the process.
2021-12-08 22:35:36,215:WARNING:override steps (5) and chunk_size (512) as content does not fit (484 byte(s) given) parameters.
2021-12-08 22:35:36,239:INFO:ascii passed initial chaos probing. Mean measured chaos is 0.000000 %
2021-12-08 22:35:36,241:INFO:ascii should target any language(s) of ['Latin Based']
2021-12-08 22:35:36,252:INFO:We detected language [('English', 1.0), ('Indonesian', 1.0), ('Simple English', 1.0)] using ascii
2021-12-08 22:35:36,252:INFO:ascii is most likely the one. Stopping the process.
2021-12-08 22:45:59,631:ERROR:JSONDecodeError: e
2021-12-08 22:46:29,483:ERROR:JSONDecodeError: Expecting value: line 1 column 1 (char 0)
2021-12-08 22:49:44,481:ERROR:JSONDecodeError: Expecting value: line 1 column 1 (char 0)
2021-12-08 22:50:33,467:ERROR:MissingSchema: Cannot make the connection with 
2021-12-08 22:53:58,273:ERROR:MissingSchema: Invalid URL '': No schema supplied. Perhaps you meant http://?
2021-12-08 22:55:16,684:ERROR:MissingSchema: Invalid URL 'dfyjd': No schema supplied. Perhaps you meant http://dfyjd?
2021-12-08 22:56:10,836:ERROR:MissingSchema: Invalid URL '65356': No schema supplied. Perhaps you meant http://65356?
2021-12-08 22:57:23,533:ERROR:ConnectionError: HTTPSConnectionPool(host='ghibliapi.herokuapp.com', port=443): Max retries exceeded with url: /films (Caused by NewConnectionError('<urllib3.connection.HTTPSConnection object at 0x0000022299C391C8>: Failed to establish a new connection: [Errno 11001] getaddrinfo failed'))
2021-12-08 23:01:09,857:ERROR:JSONDecodeError: Expecting value: line 1 column 1 (char 0)
2021-12-08 23:01:57,962:ERROR:ConnectionError: HTTPSConnectionPool(host='ghibliapi.herokapp.com', port=443): Max retries exceeded with url: /films (Caused by NewConnectionError('<urllib3.connection.HTTPSConnection object at 0x0000023A89720A48>: Failed to establish a new connection: [Errno 11001] getaddrinfo failed'))
2021-12-08 23:04:34,364:ERROR:ConnectionError: HTTPSConnectionPool(host='ghibliapi.herokapp.com', port=443): Max retries exceeded with url: /films (Caused by NewConnectionError('<urllib3.connection.HTTPSConnection object at 0x000002152F0BFAC8>: Failed to establish a new connection: [Errno 11001] getaddrinfo failed'))
2021-12-08 23:06:54,577:ERROR:JSONDecodeError: Expecting value: line 1 column 1 (char 0)
2021-12-08 23:07:11,764:ERROR:ConnectionError: HTTPSConnectionPool(host='ghibliapi.herokapp.com', port=443): Max retries exceeded with url: /films (Caused by NewConnectionError('<urllib3.connection.HTTPSConnection object at 0x00000237756428C8>: Failed to establish a new connection: [Errno 11001] getaddrinfo failed'))
2021-12-08 23:07:42,858:ERROR:ConnectionError: HTTPSConnectionPool(host='ghibliapi.herokapp.com', port=443): Max retries exceeded with url: /films (Caused by NewConnectionError('<urllib3.connection.HTTPSConnection object at 0x000001E0D5E80A08>: Failed to establish a new connection: [Errno 11001] getaddrinfo failed'))
2021-12-08 23:19:46,979:ERROR:JSONDecodeError: Expecting value: line 1 column 1 (char 0)
2021-12-09 09:00:19,646:ERROR:MissingSchema: Invalid URL '1234': No schema supplied. Perhaps you meant http://1234?
2021-12-09 09:01:09,184:ERROR:MissingSchema: Invalid URL '1234': No schema supplied. Perhaps you meant http://1234?
2021-12-09 09:12:07,080:ERROR:TypeError: 'NoneType' object is not iterable
2021-12-09 09:46:09,286:ERROR:TypeError: lookup() argument must be str, not None
2021-12-09 09:49:46,863:ERROR:TypeError: lookup() argument must be str, not None
2021-12-09 09:50:55,891:ERROR:ConnectionError: HTTPSConnectionPool(host='ghibliapi.herokuapp.com', port=443): Max retries exceeded with url: /films (Caused by NewConnectionError('<urllib3.connection.HTTPSConnection object at 0x0000029CB6F97B08>: Failed to establish a new connection: [Errno 11001] getaddrinfo failed'))
2021-12-09 12:20:00,501:ERROR:PermissionError: [Errno 13] Permission denied: 'ghibliStudioApi_csv.csv'
2021-12-09 12:28:26,360:ERROR:MissingSchema: Invalid URL '': No schema supplied. Perhaps you meant http://?
2021-12-09 12:28:40,392:ERROR:TypeError: 'NoneType' object is not iterable
2021-12-09 12:28:45,313:ERROR:PermissionError: [Errno 13] Permission denied: 'ghibliStudioApi_csv.csv'
2021-12-09 12:34:51,365:ERROR:MissingSchema: Invalid URL '': No schema supplied. Perhaps you meant http://?
2021-12-09 12:35:11,618:ERROR:TypeError: 'NoneType' object is not iterable
2021-12-09 12:38:36,948:ERROR:TypeError: 'NoneType' object is not iterable
2021-12-09 12:39:40,083:ERROR:TypeError: 'NoneType' object is not iterable
2021-12-09 12:45:16,132:ERROR:TypeError: 'NoneType' object is not iterable
2021-12-09 12:46:02,927:ERROR:TypeError: 'NoneType' object is not iterable
2021-12-09 12:47:03,815:ERROR:ConnectionError: HTTPSConnectionPool(host='ghibliapi.herokuapp.com', port=443): Max retries exceeded with url: /films (Caused by NewConnectionError('<urllib3.connection.HTTPSConnection object at 0x0000027370195608>: Failed to establish a new connection: [Errno 11001] getaddrinfo failed'))
2021-12-09 12:47:13,537:ERROR:TypeError: 'NoneType' object is not iterable
2021-12-09 12:48:05,791:ERROR:ConnectionError: HTTPSConnectionPool(host='ghibliapi.herokuapp.com', port=443): Max retries exceeded with url: /films (Caused by NewConnectionError('<urllib3.connection.HTTPSConnection object at 0x000002034F58DE48>: Failed to establish a new connection: [Errno 11001] getaddrinfo failed'))
2021-12-09 12:48:10,844:ERROR:TypeError: 'NoneType' object is not iterable
2021-12-09 12:50:57,448:ERROR:ConnectionError: HTTPSConnectionPool(host='ghibliapi.herokuapp.com', port=443): Max retries exceeded with url: /films (Caused by NewConnectionError('<urllib3.connection.HTTPSConnection object at 0x000001482638FE08>: Failed to establish a new connection: [Errno 11001] getaddrinfo failed'))
2021-12-09 12:51:36,801:ERROR:ConnectionError: HTTPSConnectionPool(host='ghibliapi.herokuapp.com', port=443): Max retries exceeded with url: /films (Caused by NewConnectionError('<urllib3.connection.HTTPSConnection object at 0x000001AE01D6FE48>: Failed to establish a new connection: [Errno 11001] getaddrinfo failed'))
2021-12-09 12:51:37,349:INFO:Couldn't make the connection
2021-12-09 12:57:57,250:ERROR:PermissionError: [Errno 13] Permission denied: 'ghibliStudioApi_csv.csv'
2021-12-09 12:57:57,250:INFO:Cannot edit the file ghibliStudioApi_csv.csv
2021-12-09 13:09:31,756:ERROR:ConnectionError: HTTPSConnectionPool(host='ghibliapi.heokuapp.com', port=443): Max retries exceeded with url: /films (Caused by NewConnectionError('<urllib3.connection.HTTPSConnection object at 0x00000200FA348508>: Failed to establish a new connection: [WinError 10013] An attempt was made to access a socket in a way forbidden by its access permissions'))
2021-12-09 13:09:33,039:INFO:Couldn't make the connection
2021-12-09 13:18:56,211:ERROR:JSONDecodeError: Expecting value: line 1 column 1 (char 0)
2021-12-09 13:19:35,057:ERROR:JSONDecodeError: Expecting value: line 1 column 1 (char 0)
2021-12-09 13:20:14,624:ERROR:Expecting value
2021-12-09 13:21:52,458:ERROR:JSONDecodeError: Expecting value: line 1 column 1 (char 0)
2021-12-09 13:23:19,628:ERROR:JSONDecodeError: Expecting value: line 1 column 1 (char 0)
2021-12-09 20:32:20,580:WARNING:extracted_data has null value
2021-12-09 20:32:35,509:WARNING:extracted_data has null value
2021-12-09 20:32:39,080:WARNING:extracted_data has null value
2021-12-09 20:32:42,993:WARNING:extracted_data has null value
2021-12-09 20:32:47,758:WARNING:extracted_data has null value
2021-12-09 20:32:51,244:WARNING:extracted_data has null value
2021-12-09 20:32:56,862:WARNING:extracted_data has null value
2021-12-09 20:33:00,211:WARNING:extracted_data has null value
2021-12-09 20:33:27,117:WARNING:extracted_data has null value
2021-12-09 20:33:42,923:WARNING:extracted_data has null value
2021-12-09 20:33:54,008:WARNING:extracted_data has null value
2021-12-09 20:34:23,133:WARNING:extracted_data has null value
2021-12-09 20:34:50,681:WARNING:extracted_data has null value
2021-12-09 20:35:10,896:WARNING:extracted_data has null value
2021-12-09 21:49:46,821:WARNING:extracted_data has null value
2021-12-09 21:49:47,937:WARNING:extracted_data has null value
2021-12-09 21:49:48,909:WARNING:extracted_data has null value
2021-12-09 21:49:49,907:WARNING:extracted_data has null value
2021-12-09 21:49:51,006:WARNING:extracted_data has null value
2021-12-09 21:49:51,973:WARNING:extracted_data has null value
2021-12-09 21:49:52,896:WARNING:extracted_data has null value
2021-12-09 21:49:53,998:WARNING:extracted_data has null value
2021-12-10 00:01:40,801:ERROR:MissingSchema: Invalid URL 'a value': No schema supplied. Perhaps you meant http://a value?
2021-12-10 11:02:01,578:INFO:response received in response_data is None
2021-12-10 14:17:23,592:ERROR:MissingSchema: Invalid URL '': No schema supplied. Perhaps you meant http://?
2021-12-10 15:35:57,784:ERROR:TypeError: object of type 'type' has no len()
2021-12-10 21:34:34,530:ERROR:SSLError: HTTPSConnectionPool(host='collectionapi.metmseum.org', port=443): Max retries exceeded with url: /public/collection/v1/objects (Caused by SSLError(SSLError(1, '[SSL: TLSV1_ALERT_INTERNAL_ERROR] tlsv1 alert internal error (_ssl.c:1076)')))
2021-12-10 21:34:35,988:ERROR:Couldn't make the connection
2021-12-11 14:45:42,816:ERROR:TypeError: string indices must be integers
2021-12-11 14:47:56,906:ERROR:TypeError: string indices must be integers
2021-12-11 14:48:24,726:ERROR:TypeError: string indices must be integers
2021-12-11 19:41:03,818:ERROR:AttributeError:'dict' object has no attribute 'index'
Traceback (most recent call last):
  File "C:\Users\Saatwik Mehta\PycharmProjects\codeOps_week1\StudioGhibliApi.py", line 23, in <module>
    data = object_to_fetch_data.flat_list_data(response_data, 'url')
  File "C:\Users\Saatwik Mehta\PycharmProjects\codeOps_week1\apidatahandler.py", line 82, in flat_list_data
    data_dict[key][data_dict.index(item)] = item_data['name']
AttributeError: 'dict' object has no attribute 'index'
2021-12-11 19:43:33,390:ERROR:TypeError:sequence item 0: expected str instance, generator found
Traceback (most recent call last):
  File "C:\Users\Saatwik Mehta\PycharmProjects\codeOps_week1\StudioGhibliApi.py", line 23, in <module>
    data = object_to_fetch_data.flat_list_data(response_data, 'url')
  File "C:\Users\Saatwik Mehta\PycharmProjects\codeOps_week1\apidatahandler.py", line 88, in flat_list_data
    data_dict[key] = ','.join(data_dict[key]) if data_dict is not None else ''
TypeError: sequence item 0: expected str instance, generator found
2021-12-11 20:35:23,883:ERROR:TypeError:sequence item 0: expected str instance, generator found
Traceback (most recent call last):
  File "C:\Users\Saatwik Mehta\PycharmProjects\codeOps_week1\StudioGhibliApi.py", line 23, in <module>
    data = object_to_fetch_data.flat_list_data(response_data, 'url')
  File "C:\Users\Saatwik Mehta\PycharmProjects\codeOps_week1\apidatahandler.py", line 88, in flat_list_data
    data_dict[key] = ','.join(data_dict[key]) if data_dict is not None else ''
TypeError: sequence item 0: expected str instance, generator found
2021-12-11 20:52:13,115:ERROR:TypeError:sequence item 0: expected str instance, generator found
2021-12-11 21:01:26,905:INFO:ascii passed initial chaos probing. Mean measured chaos is 0.000000 %
2021-12-11 21:01:26,906:INFO:ascii should target any language(s) of ['Latin Based']
2021-12-11 21:01:26,915:INFO:We detected language [('Finnish', 1.0), ('Norwegian', 1.0), ('English', 0.99), ('Dutch', 0.9705), ('German', 0.95)] using ascii
2021-12-11 21:01:26,915:INFO:ascii is most likely the one. Stopping the process.
2021-12-12 14:40:04,645:ERROR:TypeError:to_xml() got an unexpected keyword argument 'index_label'
2021-12-12 14:51:31,481:ERROR:LookupError:unknown encoding: 'utf-8-sig'
2021-12-12 15:06:37,477:ERROR:TypeError:object of type 'NoneType' has no len()
2021-12-12 16:52:13,378:ERROR:KeyError:'name'
Traceback (most recent call last):
  File "C:\Users\Saatwik Mehta\PycharmProjects\codeOps_week1\StudioGhibliApi.py", line 16, in <module>
    data = object_to_fetch_data.fetch_nested_link_data(response_data, 'url')
  File "C:\Users\Saatwik Mehta\PycharmProjects\codeOps_week1\apidatahandler.py", line 114, in fetch_nested_link_data
    data_dict[key][data_dict[key].index(item)] = item_data['name']
KeyError: 'name'
2021-12-12 17:00:23,655:ERROR:MissingSchema:Invalid URL 'TODO': No schema supplied. Perhaps you meant http://TODO?
Traceback (most recent call last):
  File "C:\Users\Saatwik Mehta\PycharmProjects\codeOps_week1\StudioGhibliApi.py", line 16, in <module>
    data = object_to_fetch_data.fetch_nested_link_data(response_data, 'url')
  File "C:\Users\Saatwik Mehta\PycharmProjects\codeOps_week1\apidatahandler.py", line 110, in fetch_nested_link_data
    response = requests.get(item)
  File "C:\Users\Saatwik Mehta\PycharmProjects\codeOps_week1\venv\lib\site-packages\requests\api.py", line 75, in get
    return request('get', url, params=params, **kwargs)
  File "C:\Users\Saatwik Mehta\PycharmProjects\codeOps_week1\venv\lib\site-packages\requests\api.py", line 61, in request
    return session.request(method=method, url=url, **kwargs)
  File "C:\Users\Saatwik Mehta\PycharmProjects\codeOps_week1\venv\lib\site-packages\requests\sessions.py", line 528, in request
    prep = self.prepare_request(req)
  File "C:\Users\Saatwik Mehta\PycharmProjects\codeOps_week1\venv\lib\site-packages\requests\sessions.py", line 466, in prepare_request
    hooks=merge_hooks(request.hooks, self.hooks),
  File "C:\Users\Saatwik Mehta\PycharmProjects\codeOps_week1\venv\lib\site-packages\requests\models.py", line 316, in prepare
    self.prepare_url(url, params)
  File "C:\Users\Saatwik Mehta\PycharmProjects\codeOps_week1\venv\lib\site-packages\requests\models.py", line 390, in prepare_url
    raise MissingSchema(error)
requests.exceptions.MissingSchema: Invalid URL 'TODO': No schema supplied. Perhaps you meant http://TODO?
2021-12-12 20:45:12,872:ERROR:KeyError:"['title', 'original_title', 'image', 'director', 'producer', 'release_date', 'running_time', 'people', 'species', 'locations', 'vehicles'] not in index"
2021-12-13 13:25:13,392:ERROR:TypeError: type() takes 1 or 3 arguments
2021-12-13 13:41:56,079:ERROR:ConnectionError: HTTPSConnectionPool(host='ghibliapi.herokuapp.com', port=443): Max retries exceeded with url: /films (Caused by NewConnectionError('<urllib3.connection.HTTPSConnection object at 0x000001DFE8119288>: Failed to establish a new connection: [Errno 11001] getaddrinfo failed'))
2021-12-13 13:41:56,080:ERROR:Couldn't make the connection
2021-12-21 15:38:12,432:ERROR:None
2021-12-21 15:38:12,468:ERROR:None
2021-12-21 15:38:16,604:ERROR:None
2021-12-21 15:38:16,605:ERROR:None
2021-12-21 15:38:53,730:ERROR:None
2021-12-21 15:38:53,731:ERROR:None
2021-12-21 15:39:19,568:ERROR:None
2021-12-21 15:39:19,568:ERROR:None
2021-12-21 15:45:39,126:ERROR:{'ConnectionError'}: {ConnectionError(MaxRetryError("HTTPSConnectionPool(host='ghibliapi.hokuapp.com', port=443): Max retries exceeded with url: /films (Caused by NewConnectionError('<urllib3.connection.HTTPSConnection object at 0x0000019D342C8BC8>: Failed to establish a new connection: [Errno 11001] getaddrinfo failed'))"))}
2021-12-21 15:45:39,126:ERROR:Couldn't make the connection
2021-12-21 15:45:42,002:ERROR:{'ConnectionError'}: {ConnectionError(MaxRetryError("HTTPSConnectionPool(host='ghibliapi.hokuapp.com', port=443): Max retries exceeded with url: /films (Caused by NewConnectionError('<urllib3.connection.HTTPSConnection object at 0x0000025E8074AB08>: Failed to establish a new connection: [Errno 11001] getaddrinfo failed'))"))}
2021-12-21 15:45:42,003:ERROR:Couldn't make the connection
2021-12-21 15:47:01,589:ERROR:{'ConnectionError'}: {ConnectionError(MaxRetryError("HTTPSConnectionPool(host='ghibliapi.hokuapp.com', port=443): Max retries exceeded with url: /films (Caused by NewConnectionError('<urllib3.connection.HTTPSConnection object at 0x000001B8ADF18B48>: Failed to establish a new connection: [Errno 11001] getaddrinfo failed'))"))}
2021-12-21 15:47:01,589:ERROR:Couldn't make the connection
2021-12-21 15:47:33,065:ERROR:{'ConnectionError'}: {ConnectionError(MaxRetryError("HTTPSConnectionPool(host='ghibliapi.hokuapp.com', port=443): Max retries exceeded with url: /films (Caused by NewConnectionError('<urllib3.connection.HTTPSConnection object at 0x000001906F1A8A88>: Failed to establish a new connection: [Errno 11001] getaddrinfo failed'))"))}
2021-12-21 15:47:33,065:ERROR:Couldn't make the connection
2021-12-21 15:47:37,104:ERROR:{'ConnectionError'}: {ConnectionError(MaxRetryError("HTTPSConnectionPool(host='ghibliapi.hokuapp.com', port=443): Max retries exceeded with url: /films (Caused by NewConnectionError('<urllib3.connection.HTTPSConnection object at 0x000001BD5B0165C8>: Failed to establish a new connection: [Errno 11001] getaddrinfo failed'))"))}
2021-12-21 15:47:37,104:ERROR:Couldn't make the connection
2021-12-21 15:48:20,265:ERROR:{'ConnectionError'}: {ConnectionError(MaxRetryError("HTTPSConnectionPool(host='ghibliapi.hokuapp.com', port=443): Max retries exceeded with url: /films (Caused by NewConnectionError('<urllib3.connection.HTTPSConnection object at 0x000001A7AB0A1C08>: Failed to establish a new connection: [Errno 11001] getaddrinfo failed'))"))}
2021-12-21 15:48:20,265:ERROR:Couldn't make the connection
2021-12-21 15:48:41,405:ERROR:{'ConnectionError'}: {ConnectionError(MaxRetryError("HTTPSConnectionPool(host='ghibliapi.hokuapp.com', port=443): Max retries exceeded with url: /films (Caused by NewConnectionError('<urllib3.connection.HTTPSConnection object at 0x00000171CDCF8A48>: Failed to establish a new connection: [Errno 11001] getaddrinfo failed'))"))}
2021-12-21 15:48:41,405:ERROR:Couldn't make the connection
2021-12-21 15:49:04,692:ERROR:{'ConnectionError'}: {ConnectionError(MaxRetryError("HTTPSConnectionPool(host='ghibliapi.hokuapp.com', port=443): Max retries exceeded with url: /films (Caused by NewConnectionError('<urllib3.connection.HTTPSConnection object at 0x000001B9AD022D88>: Failed to establish a new connection: [Errno 11001] getaddrinfo failed'))"))}
2021-12-21 15:49:04,693:ERROR:Couldn't make the connection
2021-12-21 15:49:36,520:ERROR:{'ConnectionError'}: {ConnectionError(MaxRetryError("HTTPSConnectionPool(host='ghibliapi.herokuapp.com', port=443): Max retries exceeded with url: /films (Caused by NewConnectionError('<urllib3.connection.HTTPSConnection object at 0x00000274CAAE8C08>: Failed to establish a new connection: [Errno 11001] getaddrinfo failed'))"))}
2021-12-21 15:49:36,520:ERROR:Couldn't make the connection
2021-12-21 15:51:42,223:INFO:Successfully executed
2021-12-21 15:53:24,481:INFO:Successfully executed
2021-12-21 15:55:05,526:INFO:Successfully executed
2021-12-21 15:55:09,114:INFO:Successfully executed
2021-12-21 15:59:18,965:INFO:Successfully executed
2021-12-21 15:59:22,829:INFO:Successfully executed
2021-12-21 15:59:46,136:INFO:Successfully executed
2021-12-21 15:59:50,259:INFO:Successfully executed
2021-12-21 16:00:06,086:INFO:Successfully executed
2021-12-21 16:00:46,418:INFO:Successfully executed
2021-12-21 16:01:41,820:INFO:successfully executed
2021-12-21 21:50:46,270:ERROR:{'ConnectionError'}: {ConnectionError(ProtocolError('Connection aborted.', OSError(0, 'Error')))}
2021-12-21 21:50:46,271:ERROR:Couldn't make the connection
2021-12-21 21:51:08,107:ERROR:{'ConnectionError'}: {ConnectionError(ProtocolError('Connection aborted.', OSError(0, 'Error')))}
2021-12-21 21:51:08,108:ERROR:Couldn't make the connection
2021-12-21 21:58:26,032:ERROR:{'JSONDecodeError'}: {JSONDecodeError('Expecting value: line 1 column 1 (char 0)')}
2021-12-21 21:58:51,962:ERROR:{'JSONDecodeError'}: {JSONDecodeError('Expecting value: line 1 column 1 (char 0)')}
2021-12-21 21:59:25,335:ERROR:{'JSONDecodeError'}: {JSONDecodeError('Expecting value: line 1 column 1 (char 0)')}
2021-12-21 22:08:04,887:ERROR:{'JSONDecodeError'}: {JSONDecodeError('Expecting value: line 1 column 1 (char 0)')}
2021-12-21 22:09:11,143:ERROR:JSONDecodeError: Expecting value: line 1 column 1 (char 0)
2021-12-22 00:15:52,030:ERROR:JSONDecodeError: Expecting value: line 1 column 1 (char 0)
2021-12-24 09:49:59,264:WARNING:Please provide a URL to process!
2021-12-24 09:58:04,658:ERROR:{'ConnectionError'}: {ConnectionError(MaxRetryError("HTTPSConnectionPool(host='ghibliapi.hkuapp.com', port=443): Max retries exceeded with url: /films (Caused by NewConnectionError('<urllib3.connection.HTTPSConnection object at 0x0000029ABF6F5C48>: Failed to establish a new connection: [Errno 11001] getaddrinfo failed'))"))}
2021-12-24 09:58:04,659:ERROR:Couldn't make the connection
2021-12-24 10:01:08,841:WARNING:Please provide a URL to process!
2021-12-24 14:23:57,922:WARNING:value of result is <Response [404]>
2021-12-24 14:25:17,564:WARNING:URL schema is not proper!
2021-12-24 14:25:52,375:WARNING:URL schema is not proper!
2021-12-24 14:26:13,848:WARNING:Please provide a URL to process!
